python3: can't open file '/home/y/repos/emurgo_db/reporting/best_block_server.py': [Errno 2] No such file or directory
Traceback (most recent call last):
  File "/home/yy/repos/emurgo_db/reporting/best_block_server.py", line 7, in <module>
    from tendo import singleton
ModuleNotFoundError: No module named 'tendo'
Traceback (most recent call last):
  File "/home/yy/repos/emurgo_db/reporting/best_block_server.py", line 7, in <module>
    from tendo import singleton
ModuleNotFoundError: No module named 'tendo'
Another instance is already running, quitting.
Traceback (most recent call last):
  File "/home/yy/.local/lib/python3.8/site-packages/tendo/singleton.py", line 66, in __init__
    fcntl.lockf(self.fp, fcntl.LOCK_EX | fcntl.LOCK_NB)
BlockingIOError: [Errno 11] Resource temporarily unavailable

During handling of the above exception, another exception occurred:

Traceback (most recent call last):
  File "/home/yy/repos/emurgo_db/reporting/best_block_server.py", line 9, in <module>
    me = singleton.SingleInstance()
  File "/home/yy/.local/lib/python3.8/site-packages/tendo/singleton.py", line 70, in __init__
    raise SingleInstanceException()
tendo.singleton.SingleInstanceException
Another instance is already running, quitting.
Traceback (most recent call last):
  File "/home/yy/.local/lib/python3.8/site-packages/tendo/singleton.py", line 66, in __init__
    fcntl.lockf(self.fp, fcntl.LOCK_EX | fcntl.LOCK_NB)
BlockingIOError: [Errno 11] Resource temporarily unavailable

During handling of the above exception, another exception occurred:

Traceback (most recent call last):
  File "/home/yy/repos/emurgo_db/reporting/best_block_server.py", line 9, in <module>
    me = singleton.SingleInstance()
  File "/home/yy/.local/lib/python3.8/site-packages/tendo/singleton.py", line 70, in __init__
    raise SingleInstanceException()
tendo.singleton.SingleInstanceException
Another instance is already running, quitting.
Traceback (most recent call last):
  File "/home/yy/.local/lib/python3.8/site-packages/tendo/singleton.py", line 66, in __init__
    fcntl.lockf(self.fp, fcntl.LOCK_EX | fcntl.LOCK_NB)
BlockingIOError: [Errno 11] Resource temporarily unavailable

During handling of the above exception, another exception occurred:

Traceback (most recent call last):
  File "/home/yy/repos/emurgo_db/reporting/best_block_server.py", line 9, in <module>
    me = singleton.SingleInstance()
  File "/home/yy/.local/lib/python3.8/site-packages/tendo/singleton.py", line 70, in __init__
    raise SingleInstanceException()
tendo.singleton.SingleInstanceException
Another instance is already running, quitting.
Traceback (most recent call last):
  File "/home/yy/.local/lib/python3.8/site-packages/tendo/singleton.py", line 66, in __init__
    fcntl.lockf(self.fp, fcntl.LOCK_EX | fcntl.LOCK_NB)
BlockingIOError: [Errno 11] Resource temporarily unavailable

During handling of the above exception, another exception occurred:

Traceback (most recent call last):
  File "/home/yy/repos/emurgo_db/reporting/best_block_server.py", line 9, in <module>
    me = singleton.SingleInstance()
  File "/home/yy/.local/lib/python3.8/site-packages/tendo/singleton.py", line 70, in __init__
    raise SingleInstanceException()
tendo.singleton.SingleInstanceException
Another instance is already running, quitting.
Traceback (most recent call last):
  File "/home/yy/.local/lib/python3.8/site-packages/tendo/singleton.py", line 66, in __init__
    fcntl.lockf(self.fp, fcntl.LOCK_EX | fcntl.LOCK_NB)
BlockingIOError: [Errno 11] Resource temporarily unavailable

During handling of the above exception, another exception occurred:

Traceback (most recent call last):
  File "/home/yy/repos/emurgo_db/reporting/best_block_server.py", line 9, in <module>
    me = singleton.SingleInstance()
  File "/home/yy/.local/lib/python3.8/site-packages/tendo/singleton.py", line 70, in __init__
    raise SingleInstanceException()
tendo.singleton.SingleInstanceException
Another instance is already running, quitting.
Traceback (most recent call last):
  File "/home/yy/.local/lib/python3.8/site-packages/tendo/singleton.py", line 66, in __init__
    fcntl.lockf(self.fp, fcntl.LOCK_EX | fcntl.LOCK_NB)
BlockingIOError: [Errno 11] Resource temporarily unavailable

During handling of the above exception, another exception occurred:

Traceback (most recent call last):
  File "/home/yy/repos/emurgo_db/reporting/best_block_server.py", line 9, in <module>
    me = singleton.SingleInstance()
  File "/home/yy/.local/lib/python3.8/site-packages/tendo/singleton.py", line 70, in __init__
    raise SingleInstanceException()
tendo.singleton.SingleInstanceException
Another instance is already running, quitting.
Traceback (most recent call last):
  File "/home/yy/.local/lib/python3.8/site-packages/tendo/singleton.py", line 66, in __init__
    fcntl.lockf(self.fp, fcntl.LOCK_EX | fcntl.LOCK_NB)
BlockingIOError: [Errno 11] Resource temporarily unavailable

During handling of the above exception, another exception occurred:

Traceback (most recent call last):
  File "/home/yy/repos/emurgo_db/reporting/best_block_server.py", line 9, in <module>
    me = singleton.SingleInstance()
  File "/home/yy/.local/lib/python3.8/site-packages/tendo/singleton.py", line 70, in __init__
    raise SingleInstanceException()
tendo.singleton.SingleInstanceException
Another instance is already running, quitting.
Traceback (most recent call last):
  File "/home/yy/.local/lib/python3.8/site-packages/tendo/singleton.py", line 66, in __init__
    fcntl.lockf(self.fp, fcntl.LOCK_EX | fcntl.LOCK_NB)
BlockingIOError: [Errno 11] Resource temporarily unavailable

During handling of the above exception, another exception occurred:

Traceback (most recent call last):
  File "/home/yy/repos/emurgo_db/reporting/best_block_server.py", line 9, in <module>
    me = singleton.SingleInstance()
  File "/home/yy/.local/lib/python3.8/site-packages/tendo/singleton.py", line 70, in __init__
    raise SingleInstanceException()
tendo.singleton.SingleInstanceException
